Workbook

Sheet Data
A1: Tech type | B1: Component | C1: Unit price per m2 | D1: Lifetime (year) | E1: Manufacturing Cost
A3: PV | B3: PV panel | C3: 68.94 | D3: 12 | E3: 0
A4: Spray cooling PV/T | B4: PV panel | C4: 68.94 | D4: 12 | E4: 1.818
B5: Nozzle | C5: 0.349 | D5: 1
A6: Tube plate PV/T | B6: PV panel | C6: 68.94 | D6: 12 | E6: 2.05
B7: Copper plate | C7: 8.92 | D7: 12
A8: Flat plate PV/T | B8: PV panel | C8: 68.94 | D8: 12 | E8: 3.13
B9: Glass | C9: 2.66 | D9: 12
A12: Discount Ratio | B12: PVIFA | C12: PVIFA1
A13: 8 | B13: =7.5361 -> 7.5361 | C13: =B13*(1+A13/100) -> 8.138988 | D13: =C13*$C$5 -> 2.8405068
A14: 7 | B14: =7.9427 -> 7.9427 | C14: =B14*(1+A14/100) -> 8.498689 | D14: =C14*$C$5 -> 2.9660425
A15: 6 | B15: =8.3838 -> 8.3838 | C15: =B15*(1+A15/100) -> 8.886828 | D15: =C15*$C$5 -> 3.101503
A16: 5 | B16: =8.8633 -> 8.8633 | C16: =B16*(1+A16/100) -> 9.306465 | D16: =C16*$C$5 -> 3.2479563
A17: 4 | B17: =9.3851 -> 9.3851 | C17: =B17*(1+A17/100) -> 9.760504 | D17: =C17*$C$5 -> 3.4064159
A18: 3 | B18: =9.954 -> 9.954 | C18: =B18*(1+A18/100) -> 10.25262 | D18: =C18*$C$5 -> 3.5781644
A19: 2 | B19: =10.5753 -> 10.5753 | C19: =B19*(1+A19/100) -> 10.786806 | D19: =C19*$C$5 -> 3.7645953
A20: 1 | B20: =11.2551 -> 11.2551 | C20: =B20*(1+A20/100) -> 11.367651 | D20: =C20*$C$5 -> 3.9673102
A21: 0 | B21: =12 -> 12 | C21: =B21*(1+A21/100) -> 12 | D21: =C21*$C$5 -> 4.188
A23: Initial Investment
A24: PV | B24: =C3 -> 68.94 | C24: Spray cooling PV/T | D24: =$C$4+D13+$E$4 -> 73.598507 | E24: Tube plate PV/T | F24: =C6+C7+E6 -> 79.91 | G24: Flat plate PV/T | H24: =C8+C9+E8 -> 74.73
D25: =$C$4+D14+$E$4 -> 73.724042
D26: =$C$4+D15+$E$4 -> 73.859503
D27: =$C$4+D16+$E$4 -> 74.005956
D28: =$C$4+D17+$E$4 -> 74.164416
D29: =$C$4+D18+$E$4 -> 74.336164
D30: =$C$4+D19+$E$4 -> 74.522595
D31: =$C$4+D20+$E$4 -> 74.72531
D32: =$C$4+D21+$E$4 -> 74.946

Sheet Spray cooling PVT result
A1: PV Total Lifetime Cost | D1: Spray cooling PV/T
A2: Discount Ratio | B2: Value | E2: 3 | F2: 4 | G2: 5 | H2: 6 | I2: 7 | J2: 8 | K2: 9 | L2: 10 | O2: 3 | P2: 4 | Q2: 5 | R2: 6 | S2: 7 | T2: 8 | U2: 9 | V2: 10
A3: 8 | B3: =Data!$B$24+Data!$B$24*0.03*Data!B13 -> 84.526162 | D3: 0 | E3: =(Data!$C$4+Data!$E$4+Data!$C$5*$A$40)+(Data!$C$4+Data!$E$4+Data!$C$5*$A$40)*E2/100*$A$27 -> 99.956535 | F3: =(Data!$C$4+Data!$E$4+Data!$C$5*$A$40)+(Data!$C$4+Data!$E$4+Data!$C$5*$A$40)*F2/100*$A$27 -> 108.36694 | G3: =(Data!$C$4+Data!$E$4+Data!$C$5*$A$40)+(Data!$C$4+Data!$E$4+Data!$C$5*$A$40)*G2/100*$A$27 -> 116.77735 | H3: =(Data!$C$4+Data!$E$4+Data!$C$5*$A$40)+(Data!$C$4+Data!$E$4+Data!$C$5*$A$40)*H2/100*$A$27 -> 125.18776 | I3: =(Data!$C$4+Data!$E$4+Data!$C$5*$A$40)+(Data!$C$4+Data!$E$4+Data!$C$5*$A$40)*I2/100*$A$27 -> 133.59817 | J3: =(Data!$C$4+Data!$E$4+Data!$C$5*$A$40)+(Data!$C$4+Data!$E$4+Data!$C$5*$A$40)*J2/100*$A$27 -> 142.00858 | K3: =(Data!$C$4+Data!$E$4+Data!$C$5*$A$40)+(Data!$C$4+Data!$E$4+Data!$C$5*$A$40)*K2/100*$A$27 -> 150.41899 | L3: =(Data!$C$4+Data!$E$4+Data!$C$5*$A$40)+(Data!$C$4+Data!$E$4+Data!$C$5*$A$40)*L2/100*$A$27 -> 158.82939 | N3: 0 | O3: =(Data!$C$4+Data!$E$4+Data!$C$5*$A$40)+(Data!$C$4+Data!$E$4+Data!$C$5*$A$40)*O2/100*$A$27 -> 99.956535 | P3: =(Data!$C$4+Data!$E$4+Data!$C$5*$A$40)+(Data!$C$4+Data!$E$4+Data!$C$5*$A$40)*P2/100*$A$27 -> 108.36694 | Q3: =(Data!$C$4+Data!$E$4+Data!$C$5*$A$40)+(Data!$C$4+Data!$E$4+Data!$C$5*$A$40)*Q2/100*$A$27 -> 116.77735 | R3: =(Data!$C$4+Data!$E$4+Data!$C$5*$A$40)+(Data!$C$4+Data!$E$4+Data!$C$5*$A$40)*R2/100*$A$27 -> 125.18776 | S3: =(Data!$C$4+Data!$E$4+Data!$C$5*$A$40)+(Data!$C$4+Data!$E$4+Data!$C$5*$A$40)*S2/100*$A$27 -> 133.59817 | T3: =(Data!$C$4+Data!$E$4+Data!$C$5*$A$40)+(Data!$C$4+Data!$E$4+Data!$C$5*$A$40)*T2/100*$A$27 -> 142.00858 | U3: =(Data!$C$4+Data!$E$4+Data!$C$5*$A$40)+(Data!$C$4+Data!$E$4+Data!$C$5*$A$40)*U2/100*$A$27 -> 150.41899 | V3: =(Data!$C$4+Data!$E$4+Data!$C$5*$A$40)+(Data!$C$4+Data!$E$4+Data!$C$5*$A$40)*V2/100*$A$27 -> 158.82939
A4: 7 | B4: =Data!$B$24+Data!$B$24*0.03*Data!B14 -> 85.367092 | D4: 1 | E4: 90.237878 | F4: 95.784335 | G4: 101.33079 | H4: 106.87725 | I4: 112.42371 | J4: 117.97016 | K4: 123.51662 | L4: 129.06308 | N4: 1 | O4: 90.237878 | P4: 95.784335 | Q4: 101.33079 | R4: 106.87725 | S4: 112.42371 | T4: 117.97016 | U4: 123.51662 | V4: 129.06308
A5: 6 | B5: =Data!$B$24+Data!$B$24*0.03*Data!B15 -> 86.279375 | D5: 2 | E5: 90.237878 | F5: 95.784335 | G5: 101.33079 | H5: 106.87725 | I5: 112.42371 | J5: 117.97016 | K5: 123.51662 | L5: 129.06308 | N5: 2 | O5: 90.237878 | P5: 95.784335 | Q5: 101.33079 | R5: 106.87725 | S5: 112.42371 | T5: 117.97016 | U5: 123.51662 | V5: 129.06308
A6: 5 | B6: =Data!$B$24+Data!$B$24*0.03*Data!B16 -> 87.271077 | D6: 3 | E6: 90.237878 | F6: 95.784335 | G6: 101.33079 | H6: 106.87725 | I6: 112.42371 | J6: 117.97016 | K6: 123.51662 | L6: 129.06308 | N6: 3 | O6: 90.237878 | P6: 95.784335 | Q6: 101.33079 | R6: 106.87725 | S6: 112.42371 | T6: 117.97016 | U6: 123.51662 | V6: 129.06308
A7: 4 | B7: =Data!$B$24+Data!$B$24*0.03*Data!B17 -> 88.350264 | D7: 4 | E7: 90.237878 | F7: 95.784335 | G7: 101.33079 | H7: 106.87725 | I7: 112.42371 | J7: 117.97016 | K7: 123.51662 | L7: 129.06308 | N7: 4 | O7: 90.237878 | P7: 95.784335 | Q7: 101.33079 | R7: 106.87725 | S7: 112.42371 | T7: 117.97016 | U7: 123.51662 | V7: 129.06308
A8: 3 | B8: =Data!$B$24+Data!$B$24*0.03*Data!B18 -> 89.526863 | D8: 5 | E8: 90.237878 | F8: 95.784335 | G8: 101.33079 | H8: 106.87725 | I8: 112.42371 | J8: 117.97016 | K8: 123.51662 | L8: 129.06308 | N8: 5 | O8: 90.237878 | P8: 95.784335 | Q8: 101.33079 | R8: 106.87725 | S8: 112.42371 | T8: 117.97016 | U8: 123.51662 | V8: 129.06308
A9: 2 | B9: =Data!$B$24+Data!$B$24*0.03*Data!B19 -> 90.811835 | D9: 6 | E9: 90.237878 | F9: 95.784335 | G9: 101.33079 | H9: 106.87725 | I9: 112.42371 | J9: 117.97016 | K9: 123.51662 | L9: 129.06308 | N9: 6 | O9: 90.237878 | P9: 95.784335 | Q9: 101.33079 | R9: 106.87725 | S9: 112.42371 | T9: 117.97016 | U9: 123.51662 | V9: 129.06308
A10: 1 | B10: =Data!$B$24+Data!$B$24*0.03*Data!B20 -> 92.217798 | D10: 7 | E10: 90.237878 | F10: 95.784335 | G10: 101.33079 | H10: 106.87725 | I10: 112.42371 | J10: 117.97016 | K10: 123.51662 | L10: 129.06308 | N10: 7 | O10: 90.237878 | P10: 95.784335 | Q10: 101.33079 | R10: 106.87725 | S10: 112.42371 | T10: 117.97016 | U10: 123.51662 | V10: 129.06308
A11: 0 | B11: =Data!$B$24+Data!$B$24*0.03*Data!B21 -> 93.7584 | D11: 8 | E11: 90.237878 | F11: 95.784335 | G11: 101.33079 | H11: 106.87725 | I11: 112.42371 | J11: 117.97016 | K11: 123.51662 | L11: 129.06308 | N11: 8 | O11: 90.237878 | P11: 95.784335 | Q11: 101.33079 | R11: 106.87725 | S11: 112.42371 | T11: 117.97016 | U11: 123.51662 | V11: 129.06308
A12: Choosed Value | D12: 9 | E12: 90.237878 | F12: 95.784335 | G12: 101.33079 | H12: 106.87725 | I12: 112.42371 | J12: 117.97016 | K12: 123.51662 | L12: 129.06308 | N12: 9 | O12: 90.237878 | P12: 95.784335 | Q12: 101.33079 | R12: 106.87725 | S12: 112.42371 | T12: 117.97016 | U12: 123.51662 | V12: 129.06308
A13: 92.217798 | D13: 10 | E13: 90.237878 | F13: 95.784335 | G13: 101.33079 | H13: 106.87725 | I13: 112.42371 | J13: 117.97016 | K13: 123.51662 | L13: 129.06308 | N13: 10 | O13: 90.237878 | P13: 95.784335 | Q13: 101.33079 | R13: 106.87725 | S13: 112.42371 | T13: 117.97016 | U13: 123.51662 | V13: 129.06308
A15: PVIFA | E15: 3 | F15: 4 | G15: 5 | H15: 6 | I15: 7 | J15: 8 | K15: 9 | L15: 10 | O15: 3 | P15: 4 | Q15: 5 | R15: 6 | S15: 7 | T15: 8 | U15: 9 | V15: 10
A16: Discount Ratio | B16: Value | D16: 0 | E16: =E3/(1+$D$16/100)/$A$13 -> 1.083918 | F16: =F3/(1+$D$16/100)/$A$13 -> 1.1751196 | G16: =G3/(1+$D$16/100)/$A$13 -> 1.2663212 | H16: =H3/(1+$D$16/100)/$A$13 -> 1.3575228 | I16: =I3/(1+$D$16/100)/$A$13 -> 1.4487243 | J16: =J3/(1+$D$16/100)/$A$13 -> 1.5399259 | K16: =K3/(1+$D$16/100)/$A$13 -> 1.6311275 | L16: =L3/(1+$D$16/100)/$A$13 -> 1.7223291 | N16: 0 | O16: =O3/(2+$D$16/100)/$A$13 -> 0.54195902 | P16: =P3/(2+$D$16/100)/$A$13 -> 0.58755981 | Q16: =Q3/(2+$D$16/100)/$A$13 -> 0.6331606 | R16: =R3/(2+$D$16/100)/$A$13 -> 0.67876139 | S16: =S3/(2+$D$16/100)/$A$13 -> 0.72436217 | T16: =T3/(2+$D$16/100)/$A$13 -> 0.76996296 | U16: =U3/(2+$D$16/100)/$A$13 -> 0.81556375 | V16: =V3/(2+$D$16/100)/$A$13 -> 0.86116454
A17: 8 | B17: 7.5361 | D17: 1 | E17: =E4/(1+D17/100)/$A$13 -> 0.96884154 | F17: =F4/(1+D17/100)/$A$13 -> 1.0283912 | G17: =G4/(1+D17/100)/$A$13 -> 1.0879409 | H17: =H4/(1+D17/100)/$A$13 -> 1.1474906 | I17: =I4/(1+D17/100)/$A$13 -> 1.2070403 | J17: =J4/(1+D17/100)/$A$13 -> 1.26659 | K17: =K4/(1+D17/100)/$A$13 -> 1.3261397 | L17: =L4/(1+D17/100)/$A$13 -> 1.3856894 | N17: 1 | O17: =O4/(2+N17/100)/$A$13 -> 0.48683083 | P17: =P4/(2+N17/100)/$A$13 -> 0.51675381 | Q17: =Q4/(2+N17/100)/$A$13 -> 0.54667679 | R17: =R4/(2+N17/100)/$A$13 -> 0.57659977 | S17: =S4/(2+N17/100)/$A$13 -> 0.60652275 | T17: =T4/(2+N17/100)/$A$13 -> 0.63644573 | U17: =U4/(2+N17/100)/$A$13 -> 0.66636871 | V17: =V4/(2+N17/100)/$A$13 -> 0.69629169
A18: 7 | B18: 7.9427 | D18: 2 | E18: =E5/(1+D18/100)/$A$13 -> 0.9593431 | F18: =F5/(1+D18/100)/$A$13 -> 1.018309 | G18: =G5/(1+D18/100)/$A$13 -> 1.0772748 | H18: =H5/(1+D18/100)/$A$13 -> 1.1362407 | I18: =I5/(1+D18/100)/$A$13 -> 1.1952066 | J18: =J5/(1+D18/100)/$A$13 -> 1.2541725 | K18: =K5/(1+D18/100)/$A$13 -> 1.3131383 | L18: =L5/(1+D18/100)/$A$13 -> 1.3721042 | N18: 2 | O18: =O5/(2+N18/100)/$A$13 -> 0.48442077 | P18: =P5/(2+N18/100)/$A$13 -> 0.51419562 | Q18: =Q5/(2+N18/100)/$A$13 -> 0.54397047 | R18: =R5/(2+N18/100)/$A$13 -> 0.57374531 | S18: =S5/(2+N18/100)/$A$13 -> 0.60352016 | T18: =T5/(2+N18/100)/$A$13 -> 0.63329501 | U18: =U5/(2+N18/100)/$A$13 -> 0.66306985 | V18: =V5/(2+N18/100)/$A$13 -> 0.6928447
A19: 6 | B19: 8.3838 | D19: 3 | E19: =E6/(1+D19/100)/$A$13 -> 0.95002909 | F19: =F6/(1+D19/100)/$A$13 -> 1.0084225 | G19: =G6/(1+D19/100)/$A$13 -> 1.0668159 | H19: =H6/(1+D19/100)/$A$13 -> 1.1252093 | I19: =I6/(1+D19/100)/$A$13 -> 1.1836026 | J19: =J6/(1+D19/100)/$A$13 -> 1.241996 | K19: =K6/(1+D19/100)/$A$13 -> 1.3003894 | L19: =L6/(1+D19/100)/$A$13 -> 1.3587828 | N19: 3 | O19: =O6/(2+N19/100)/$A$13 -> 0.48203446 | P19: =P6/(2+N19/100)/$A$13 -> 0.51166264 | Q19: =Q6/(2+N19/100)/$A$13 -> 0.54129081 | R19: =R6/(2+N19/100)/$A$13 -> 0.57091898 | S19: =S6/(2+N19/100)/$A$13 -> 0.60054715 | T19: =T6/(2+N19/100)/$A$13 -> 0.63017533 | U19: =U6/(2+N19/100)/$A$13 -> 0.6598035 | V19: =V6/(2+N19/100)/$A$13 -> 0.68943167
A20: 5 | B20: 8.8633 | D20: 4 | E20: =E7/(1+D20/100)/$A$13 -> 0.94089419 | F20: =F7/(1+D20/100)/$A$13 -> 0.99872611 | G20: =G7/(1+D20/100)/$A$13 -> 1.056558 | H20: =H7/(1+D20/100)/$A$13 -> 1.1143899 | I20: =I7/(1+D20/100)/$A$13 -> 1.1722219 | J20: =J7/(1+D20/100)/$A$13 -> 1.2300538 | K20: =K7/(1+D20/100)/$A$13 -> 1.2878857 | L20: =L7/(1+D20/100)/$A$13 -> 1.3457176 | N20: 4 | O20: =O7/(2+N20/100)/$A$13 -> 0.47967155 | P20: =P7/(2+N20/100)/$A$13 -> 0.50915449 | Q20: =Q7/(2+N20/100)/$A$13 -> 0.53863742 | R20: =R7/(2+N20/100)/$A$13 -> 0.56812036 | S20: =S7/(2+N20/100)/$A$13 -> 0.5976033 | T20: =T7/(2+N20/100)/$A$13 -> 0.62708623 | U20: =U7/(2+N20/100)/$A$13 -> 0.65656917 | V20: =V7/(2+N20/100)/$A$13 -> 0.68605211
A21: 4 | B21: 9.3851 | D21: 5 | E21: =E8/(1+D21/100)/$A$13 -> 0.9319333 | F21: =F8/(1+D21/100)/$A$13 -> 0.98921443 | G21: =G8/(1+D21/100)/$A$13 -> 1.0464956 | H21: =H8/(1+D21/100)/$A$13 -> 1.1037767 | I21: =I8/(1+D21/100)/$A$13 -> 1.1610578 | J21: =J8/(1+D21/100)/$A$13 -> 1.218339 | K21: =K8/(1+D21/100)/$A$13 -> 1.2756201 | L21: =L8/(1+D21/100)/$A$13 -> 1.3329012 | N21: 5 | O21: =O8/(2+N21/100)/$A$13 -> 0.47733169 | P21: =P8/(2+N21/100)/$A$13 -> 0.50667081 | Q21: =Q8/(2+N21/100)/$A$13 -> 0.53600992 | R21: =R8/(2+N21/100)/$A$13 -> 0.56534904 | S21: =S8/(2+N21/100)/$A$13 -> 0.59468816 | T21: =T8/(2+N21/100)/$A$13 -> 0.62402728 | U21: =U8/(2+N21/100)/$A$13 -> 0.65336639 | V21: =V8/(2+N21/100)/$A$13 -> 0.68270551
A22: 3 | B22: 9.954 | D22: 6 | E22: =E9/(1+D22/100)/$A$13 -> 0.92314147 | F22: =F9/(1+D22/100)/$A$13 -> 0.97988222 | G22: =G9/(1+D22/100)/$A$13 -> 1.036623 | H22: =H9/(1+D22/100)/$A$13 -> 1.0933637 | I22: =I9/(1+D22/100)/$A$13 -> 1.1501045 | J22: =J9/(1+D22/100)/$A$13 -> 1.2068452 | K22: =K9/(1+D22/100)/$A$13 -> 1.2635859 | L22: =L9/(1+D22/100)/$A$13 -> 1.3203267 | N22: 6 | O22: =O9/(2+N22/100)/$A$13 -> 0.47501454 | P22: =P9/(2+N22/100)/$A$13 -> 0.50421124 | Q22: =Q9/(2+N22/100)/$A$13 -> 0.53340793 | R22: =R9/(2+N22/100)/$A$13 -> 0.56260463 | S22: =S9/(2+N22/100)/$A$13 -> 0.59180132 | T22: =T9/(2+N22/100)/$A$13 -> 0.62099802 | U22: =U9/(2+N22/100)/$A$13 -> 0.65019471 | V22: =V9/(2+N22/100)/$A$13 -> 0.67939141
A23: 2 | B23: 10.5753 | D23: 7 | E23: =E10/(1+D23/100)/$A$13 -> 0.91451398 | F23: =F10/(1+D23/100)/$A$13 -> 0.97072444 | G23: =G10/(1+D23/100)/$A$13 -> 1.0269349 | H23: =H10/(1+D23/100)/$A$13 -> 1.0831454 | I23: =I10/(1+D23/100)/$A$13 -> 1.1393558 | J23: =J10/(1+D23/100)/$A$13 -> 1.1955663 | K23: =K10/(1+D23/100)/$A$13 -> 1.2517767 | L23: =L10/(1+D23/100)/$A$13 -> 1.3079872 | N23: 7 | O23: =O10/(2+N23/100)/$A$13 -> 0.47271979 | P23: =P10/(2+N23/100)/$A$13 -> 0.50177544 | Q23: =Q10/(2+N23/100)/$A$13 -> 0.53083108 | R23: =R10/(2+N23/100)/$A$13 -> 0.55988673 | S23: =S10/(2+N23/100)/$A$13 -> 0.58894238 | T23: =T10/(2+N23/100)/$A$13 -> 0.61799803 | U23: =U10/(2+N23/100)/$A$13 -> 0.64705367 | V23: =V10/(2+N23/100)/$A$13 -> 0.67610932
A24: 1 | B24: 11.2551 | D24: 8 | E24: =E11/(1+D24/100)/$A$13 -> 0.90604626 | F24: =F11/(1+D24/100)/$A$13 -> 0.96173625 | G24: =G11/(1+D24/100)/$A$13 -> 1.0174262 | H24: =H11/(1+D24/100)/$A$13 -> 1.0731162 | I24: =I11/(1+D24/100)/$A$13 -> 1.1288062 | J24: =J11/(1+D24/100)/$A$13 -> 1.1844962 | K24: =K11/(1+D24/100)/$A$13 -> 1.2401862 | L24: =L11/(1+D24/100)/$A$13 -> 1.2958762 | N24: 8 | O24: =O11/(2+N24/100)/$A$13 -> 0.4704471 | P24: =P11/(2+N24/100)/$A$13 -> 0.49936305 | Q24: =Q11/(2+N24/100)/$A$13 -> 0.52827901 | R24: =R11/(2+N24/100)/$A$13 -> 0.55719497 | S24: =S11/(2+N24/100)/$A$13 -> 0.58611093 | T24: =T11/(2+N24/100)/$A$13 -> 0.61502688 | U24: =U11/(2+N24/100)/$A$13 -> 0.64394284 | V24: =V11/(2+N24/100)/$A$13 -> 0.6728588
A25: 0 | B25: 12 | D25: 9 | E25: =E12/(1+D25/100)/$A$13 -> 0.89773391 | F25: =F12/(1+D25/100)/$A$13 -> 0.95291298 | G25: =G12/(1+D25/100)/$A$13 -> 1.0080921 | H25: =H12/(1+D25/100)/$A$13 -> 1.0632711 | I25: =I12/(1+D25/100)/$A$13 -> 1.1184502 | J25: =J12/(1+D25/100)/$A$13 -> 1.1736293 | K25: =K12/(1+D25/100)/$A$13 -> 1.2288084 | L25: =L12/(1+D25/100)/$A$13 -> 1.2839874 | N25: 9 | O25: =O12/(2+N25/100)/$A$13 -> 0.46819615 | P25: =P12/(2+N25/100)/$A$13 -> 0.49697376 | Q25: =Q12/(2+N25/100)/$A$13 -> 0.52575136 | R25: =R12/(2+N25/100)/$A$13 -> 0.55452896 | S25: =S12/(2+N25/100)/$A$13 -> 0.58330657 | T25: =T12/(2+N25/100)/$A$13 -> 0.61208417 | U25: =U12/(2+N25/100)/$A$13 -> 0.64086177 | V25: =V12/(2+N25/100)/$A$13 -> 0.66963938
A26: Choosed Value | D26: 10 | E26: =E13/(1+D26/100)/$A$13 -> 0.88957269 | F26: =F13/(1+D26/100)/$A$13 -> 0.94425014 | G26: =G13/(1+D26/100)/$A$13 -> 0.99892758 | H26: =H13/(1+D26/100)/$A$13 -> 1.053605 | I26: =I13/(1+D26/100)/$A$13 -> 1.1082825 | J26: =J13/(1+D26/100)/$A$13 -> 1.1629599 | K26: =K13/(1+D26/100)/$A$13 -> 1.2176374 | L26: =L13/(1+D26/100)/$A$13 -> 1.2723148 | N26: 10 | O26: =O13/(2+N26/100)/$A$13 -> 0.46596665 | P26: =P13/(2+N26/100)/$A$13 -> 0.49460721 | Q26: =Q13/(2+N26/100)/$A$13 -> 0.52324778 | R26: =R13/(2+N26/100)/$A$13 -> 0.55188835 | S26: =S13/(2+N26/100)/$A$13 -> 0.58052892 | T26: =T13/(2+N26/100)/$A$13 -> 0.60916948 | U26: =U13/(2+N26/100)/$A$13 -> 0.63781005 | V26: =V13/(2+N26/100)/$A$13 -> 0.66645062
A27: 11.2551
A28: PVIFA1
A29: Discount Ratio | B29: Value | D29: Only consider electricity | N29: Include thermal power (treat as equal to pv power)
A30: 8 | B30: 8.138988 | E30: O&M Ratio | O30: O&M Ratio
A31: 7 | B31: 8.498689 | E31: 3 | F31: 4 | G31: 5 | H31: 6 | I31: 7 | J31: 8 | K31: 9 | L31: 10 | O31: 3 | P31: 4 | Q31: 5 | R31: 6 | S31: 7 | T31: 8 | U31: 9 | V31: 10
A32: 6 | B32: 8.886828 | C32: Output Power Improvement Ratio | D32: 0 | E32: =E16 -> 1.083918 | F32: =F16 -> 1.1751196 | G32: =G16 -> 1.2663212 | H32: =H16 -> 1.3575228 | I32: =I16 -> 1.4487243 | J32: =J16 -> 1.5399259 | K32: =K16 -> 1.6311275 | L32: =L16 -> 1.7223291 | M32: Output Power Improvement Ratio | N32: 0 | O32: =O16 -> 0.54195902 | P32: =P16 -> 0.58755981 | Q32: =Q16 -> 0.6331606 | R32: =R16 -> 0.67876139 | S32: =S16 -> 0.72436217 | T32: =T16 -> 0.76996296 | U32: =U16 -> 0.81556375 | V32: =V16 -> 0.86116454
A33: 5 | B33: 9.306465 | D33: 1 | E33: =E17 -> 0.96884154 | F33: =F17 -> 1.0283912 | G33: =G17 -> 1.0879409 | H33: =H17 -> 1.1474906 | I33: =I17 -> 1.2070403 | J33: =J17 -> 1.26659 | K33: =K17 -> 1.3261397 | L33: =L17 -> 1.3856894 | N33: 1 | O33: =O17 -> 0.48683083 | P33: =P17 -> 0.51675381 | Q33: =Q17 -> 0.54667679 | R33: =R17 -> 0.57659977 | S33: =S17 -> 0.60652275 | T33: =T17 -> 0.63644573 | U33: =U17 -> 0.66636871 | V33: =V17 -> 0.69629169
A34: 4 | B34: 9.760504 | D34: 2 | E34: =E18 -> 0.9593431 | F34: =F18 -> 1.018309 | G34: =G18 -> 1.0772748 | H34: =H18 -> 1.1362407 | I34: =I18 -> 1.1952066 | J34: =J18 -> 1.2541725 | K34: =K18 -> 1.3131383 | L34: =L18 -> 1.3721042 | N34: 2 | O34: =O18 -> 0.48442077 | P34: =P18 -> 0.51419562 | Q34: =Q18 -> 0.54397047 | R34: =R18 -> 0.57374531 | S34: =S18 -> 0.60352016 | T34: =T18 -> 0.63329501 | U34: =U18 -> 0.66306985 | V34: =V18 -> 0.6928447
A35: 3 | B35: 10.25262 | D35: 3 | E35: =E19 -> 0.95002909 | F35: =F19 -> 1.0084225 | G35: =G19 -> 1.0668159 | H35: =H19 -> 1.1252093 | I35: =I19 -> 1.1836026 | J35: =J19 -> 1.241996 | K35: =K19 -> 1.3003894 | L35: =L19 -> 1.3587828 | N35: 3 | O35: =O19 -> 0.48203446 | P35: =P19 -> 0.51166264 | Q35: =Q19 -> 0.54129081 | R35: =R19 -> 0.57091898 | S35: =S19 -> 0.60054715 | T35: =T19 -> 0.63017533 | U35: =U19 -> 0.6598035 | V35: =V19 -> 0.68943167
A36: 2 | B36: 10.786806 | D36: 4 | E36: =E20 -> 0.94089419 | F36: =F20 -> 0.99872611 | G36: =G20 -> 1.056558 | H36: =H20 -> 1.1143899 | I36: =I20 -> 1.1722219 | J36: =J20 -> 1.2300538 | K36: =K20 -> 1.2878857 | L36: =L20 -> 1.3457176 | N36: 4 | O36: =O20 -> 0.47967155 | P36: =P20 -> 0.50915449 | Q36: =Q20 -> 0.53863742 | R36: =R20 -> 0.56812036 | S36: =S20 -> 0.5976033 | T36: =T20 -> 0.62708623 | U36: =U20 -> 0.65656917 | V36: =V20 -> 0.68605211
A37: 1 | B37: 11.367651 | D37: 5 | E37: =E21 -> 0.9319333 | F37: =F21 -> 0.98921443 | G37: =G21 -> 1.0464956 | H37: =H21 -> 1.1037767 | I37: =I21 -> 1.1610578 | J37: =J21 -> 1.218339 | K37: =K21 -> 1.2756201 | L37: =L21 -> 1.3329012 | N37: 5 | O37: =O21 -> 0.47733169 | P37: =P21 -> 0.50667081 | Q37: =Q21 -> 0.53600992 | R37: =R21 -> 0.56534904 | S37: =S21 -> 0.59468816 | T37: =T21 -> 0.62402728 | U37: =U21 -> 0.65336639 | V37: =V21 -> 0.68270551
A38: 0 | B38: 12 | D38: 6 | E38: =E22 -> 0.92314147 | F38: =F22 -> 0.97988222 | G38: =G22 -> 1.036623 | H38: =H22 -> 1.0933637 | I38: =I22 -> 1.1501045 | J38: =J22 -> 1.2068452 | K38: =K22 -> 1.2635859 | L38: =L22 -> 1.3203267 | N38: 6 | O38: =O22 -> 0.47501454 | P38: =P22 -> 0.50421124 | Q38: =Q22 -> 0.53340793 | R38: =R22 -> 0.56260463 | S38: =S22 -> 0.59180132 | T38: =T22 -> 0.62099802 | U38: =U22 -> 0.65019471 | V38: =V22 -> 0.67939141
A39: Choosed Value | D39: 7 | E39: =E23 -> 0.91451398 | F39: =F23 -> 0.97072444 | G39: =G23 -> 1.0269349 | H39: =H23 -> 1.0831454 | I39: =I23 -> 1.1393558 | J39: =J23 -> 1.1955663 | K39: =K23 -> 1.2517767 | L39: =L23 -> 1.3079872 | N39: 7 | O39: =O23 -> 0.47271979 | P39: =P23 -> 0.50177544 | Q39: =Q23 -> 0.53083108 | R39: =R23 -> 0.55988673 | S39: =S23 -> 0.58894238 | T39: =T23 -> 0.61799803 | U39: =U23 -> 0.64705367 | V39: =V23 -> 0.67610932
A40: 11.367651 | D40: 8 | E40: =E24 -> 0.90604626 | F40: =F24 -> 0.96173625 | G40: =G24 -> 1.0174262 | H40: =H24 -> 1.0731162 | I40: =I24 -> 1.1288062 | J40: =J24 -> 1.1844962 | K40: =K24 -> 1.2401862 | L40: =L24 -> 1.2958762 | N40: 8 | O40: =O24 -> 0.4704471 | P40: =P24 -> 0.49936305 | Q40: =Q24 -> 0.52827901 | R40: =R24 -> 0.55719497 | S40: =S24 -> 0.58611093 | T40: =T24 -> 0.61502688 | U40: =U24 -> 0.64394284 | V40: =V24 -> 0.6728588
D41: 9 | E41: =E25 -> 0.89773391 | F41: =F25 -> 0.95291298 | G41: =G25 -> 1.0080921 | H41: =H25 -> 1.0632711 | I41: =I25 -> 1.1184502 | J41: =J25 -> 1.1736293 | K41: =K25 -> 1.2288084 | L41: =L25 -> 1.2839874 | N41: 9 | O41: =O25 -> 0.46819615 | P41: =P25 -> 0.49697376 | Q41: =Q25 -> 0.52575136 | R41: =R25 -> 0.55452896 | S41: =S25 -> 0.58330657 | T41: =T25 -> 0.61208417 | U41: =U25 -> 0.64086177 | V41: =V25 -> 0.66963938
...

Sheet Tube plate PVT result
A1: PV Total Lifetime Cost | D1: Tube plate PV/T
A2: Discount Ratio | B2: Value | E2: 3 | F2: 4 | G2: 5 | H2: 6 | I2: 7 | J2: 8 | K2: 9 | L2: 10 | O2: 3 | P2: 4 | Q2: 5 | R2: 6 | S2: 7 | T2: 8 | U2: 9 | V2: 10
A3: 8 | B3: =Data!$B$24+Data!$B$24*0.03*Data!B13 -> 84.526162 | D3: 0 | E3: =(Data!$F$24)+(Data!$F$24)*E2/100*$A$27 -> 106.89185 | F3: =(Data!$F$24)+(Data!$F$24)*F2/100*$A$27 -> 115.8858 | G3: =(Data!$F$24)+(Data!$F$24)*G2/100*$A$27 -> 124.87975 | H3: =(Data!$F$24)+(Data!$F$24)*H2/100*$A$27 -> 133.8737 | I3: =(Data!$F$24)+(Data!$F$24)*I2/100*$A$27 -> 142.86765 | J3: =(Data!$F$24)+(Data!$F$24)*J2/100*$A$27 -> 151.8616 | K3: =(Data!$F$24)+(Data!$F$24)*K2/100*$A$27 -> 160.85555 | L3: =(Data!$F$24)+(Data!$F$24)*L2/100*$A$27 -> 169.8495 | N3: 0 | O3: =(Data!$F$24)+(Data!$F$24)*O2/100*$A$27 -> 106.89185 | P3: =(Data!$F$24)+(Data!$F$24)*P2/100*$A$27 -> 115.8858 | Q3: =(Data!$F$24)+(Data!$F$24)*Q2/100*$A$27 -> 124.87975 | R3: =(Data!$F$24)+(Data!$F$24)*R2/100*$A$27 -> 133.8737 | S3: =(Data!$F$24)+(Data!$F$24)*S2/100*$A$27 -> 142.86765 | T3: =(Data!$F$24)+(Data!$F$24)*T2/100*$A$27 -> 151.8616 | U3: =(Data!$F$24)+(Data!$F$24)*U2/100*$A$27 -> 160.85555 | V3: =(Data!$F$24)+(Data!$F$24)*V2/100*$A$27 -> 169.8495
A4: 7 | B4: =Data!$B$24+Data!$B$24*0.03*Data!B14 -> 85.367092 | D4: 1 | E4: 97.976293 | F4: 103.99839 | G4: 110.02049 | H4: 116.04259 | I4: 122.06468 | J4: 128.08678 | K4: 134.10888 | L4: 140.13098 | N4: 1 | O4: 97.976293 | P4: 103.99839 | Q4: 110.02049 | R4: 116.04259 | S4: 122.06468 | T4: 128.08678 | U4: 134.10888 | V4: 140.13098
A5: 6 | B5: =Data!$B$24+Data!$B$24*0.03*Data!B15 -> 86.279375 | D5: 2 | E5: 97.976293 | F5: 103.99839 | G5: 110.02049 | H5: 116.04259 | I5: 122.06468 | J5: 128.08678 | K5: 134.10888 | L5: 140.13098 | N5: 2 | O5: 97.976293 | P5: 103.99839 | Q5: 110.02049 | R5: 116.04259 | S5: 122.06468 | T5: 128.08678 | U5: 134.10888 | V5: 140.13098
A6: 5 | B6: =Data!$B$24+Data!$B$24*0.03*Data!B16 -> 87.271077 | D6: 3 | E6: 97.976293 | F6: 103.99839 | G6: 110.02049 | H6: 116.04259 | I6: 122.06468 | J6: 128.08678 | K6: 134.10888 | L6: 140.13098 | N6: 3 | O6: 97.976293 | P6: 103.99839 | Q6: 110.02049 | R6: 116.04259 | S6: 122.06468 | T6: 128.08678 | U6: 134.10888 | V6: 140.13098
A7: 4 | B7: =Data!$B$24+Data!$B$24*0.03*Data!B17 -> 88.350264 | D7: 4 | E7: 97.976293 | F7: 103.99839 | G7: 110.02049 | H7: 116.04259 | I7: 122.06468 | J7: 128.08678 | K7: 134.10888 | L7: 140.13098 | N7: 4 | O7: 97.976293 | P7: 103.99839 | Q7: 110.02049 | R7: 116.04259 | S7: 122.06468 | T7: 128.08678 | U7: 134.10888 | V7: 140.13098
A8: 3 | B8: =Data!$B$24+Data!$B$24*0.03*Data!B18 -> 89.526863 | D8: 5 | E8: 97.976293 | F8: 103.99839 | G8: 110.02049 | H8: 116.04259 | I8: 122.06468 | J8: 128.08678 | K8: 134.10888 | L8: 140.13098 | N8: 5 | O8: 97.976293 | P8: 103.99839 | Q8: 110.02049 | R8: 116.04259 | S8: 122.06468 | T8: 128.08678 | U8: 134.10888 | V8: 140.13098
A9: 2 | B9: =Data!$B$24+Data!$B$24*0.03*Data!B19 -> 90.811835 | D9: 6 | E9: 97.976293 | F9: 103.99839 | G9: 110.02049 | H9: 116.04259 | I9: 122.06468 | J9: 128.08678 | K9: 134.10888 | L9: 140.13098 | N9: 6 | O9: 97.976293 | P9: 103.99839 | Q9: 110.02049 | R9: 116.04259 | S9: 122.06468 | T9: 128.08678 | U9: 134.10888 | V9: 140.13098
A10: 1 | B10: =Data!$B$24+Data!$B$24*0.03*Data!B20 -> 92.217798 | D10: 7 | E10: 97.976293 | F10: 103.99839 | G10: 110.02049 | H10: 116.04259 | I10: 122.06468 | J10: 128.08678 | K10: 134.10888 | L10: 140.13098 | N10: 7 | O10: 97.976293 | P10: 103.99839 | Q10: 110.02049 | R10: 116.04259 | S10: 122.06468 | T10: 128.08678 | U10: 134.10888 | V10: 140.13098
A11: 0 | B11: =Data!$B$24+Data!$B$24*0.03*Data!B21 -> 93.7584 | D11: 8 | E11: 97.976293 | F11: 103.99839 | G11: 110.02049 | H11: 116.04259 | I11: 122.06468 | J11: 128.08678 | K11: 134.10888 | L11: 140.13098 | N11: 8 | O11: 97.976293 | P11: 103.99839 | Q11: 110.02049 | R11: 116.04259 | S11: 122.06468 | T11: 128.08678 | U11: 134.10888 | V11: 140.13098
A12: Choosed Value | D12: 9 | E12: 97.976293 | F12: 103.99839 | G12: 110.02049 | H12: 116.04259 | I12: 122.06468 | J12: 128.08678 | K12: 134.10888 | L12: 140.13098 | N12: 9 | O12: 97.976293 | P12: 103.99839 | Q12: 110.02049 | R12: 116.04259 | S12: 122.06468 | T12: 128.08678 | U12: 134.10888 | V12: 140.13098
A13: 92.217798 | D13: 10 | E13: 97.976293 | F13: 103.99839 | G13: 110.02049 | H13: 116.04259 | I13: 122.06468 | J13: 128.08678 | K13: 134.10888 | L13: 140.13098 | N13: 10 | O13: 97.976293 | P13: 103.99839 | Q13: 110.02049 | R13: 116.04259 | S13: 122.06468 | T13: 128.08678 | U13: 134.10888 | V13: 140.13098
A15: PVIFA | E15: 3 | F15: 4 | G15: 5 | H15: 6 | I15: 7 | J15: 8 | K15: 9 | L15: 10 | O15: 3 | P15: 4 | Q15: 5 | R15: 6 | S15: 7 | T15: 8 | U15: 9 | V15: 10
A16: Discount Ratio | B16: Value | D16: 0 | E16: =E3/(1+$D$16/100)/$A$13 -> 1.1591239 | F16: =F3/(1+$D$16/100)/$A$13 -> 1.2566533 | G16: =G3/(1+$D$16/100)/$A$13 -> 1.3541828 | H16: =H3/(1+$D$16/100)/$A$13 -> 1.4517122 | I16: =I3/(1+$D$16/100)/$A$13 -> 1.5492416 | J16: =J3/(1+$D$16/100)/$A$13 -> 1.6467711 | K16: =K3/(1+$D$16/100)/$A$13 -> 1.7443005 | L16: =L3/(1+$D$16/100)/$A$13 -> 1.84183 | N16: 0 | O16: =O3/(2+$D$16/100)/$A$13 -> 0.57956194 | P16: =P3/(2+$D$16/100)/$A$13 -> 0.62832666 | Q16: =Q3/(2+$D$16/100)/$A$13 -> 0.67709138 | R16: =R3/(2+$D$16/100)/$A$13 -> 0.7258561 | S16: =S3/(2+$D$16/100)/$A$13 -> 0.77462082 | T16: =T3/(2+$D$16/100)/$A$13 -> 0.82338554 | U16: =U3/(2+$D$16/100)/$A$13 -> 0.87215027 | V16: =V3/(2+$D$16/100)/$A$13 -> 0.92091499
A17: 8 | B17: 7.5361 | D17: 1 | E17: =E4/(1+D17/100)/$A$13 -> 1.0519253 | F17: =F4/(1+D17/100)/$A$13 -> 1.1165817 | G17: =G4/(1+D17/100)/$A$13 -> 1.1812381 | H17: =H4/(1+D17/100)/$A$13 -> 1.2458945 | I17: =I4/(1+D17/100)/$A$13 -> 1.3105509 | J17: =J4/(1+D17/100)/$A$13 -> 1.3752074 | K17: =K4/(1+D17/100)/$A$13 -> 1.4398638 | L17: =L4/(1+D17/100)/$A$13 -> 1.5045202 | N17: 1 | O17: =O4/(2+N17/100)/$A$13 -> 0.52857936 | P17: =P4/(2+N17/100)/$A$13 -> 0.5610684 | Q17: =Q4/(2+N17/100)/$A$13 -> 0.59355745 | R17: =R4/(2+N17/100)/$A$13 -> 0.6260465 | S17: =S4/(2+N17/100)/$A$13 -> 0.65853555 | T17: =T4/(2+N17/100)/$A$13 -> 0.69102459 | U17: =U4/(2+N17/100)/$A$13 -> 0.72351364 | V17: =V4/(2+N17/100)/$A$13 -> 0.75600269
A18: 7 | B18: 7.9427 | D18: 2 | E18: =E5/(1+D18/100)/$A$13 -> 1.0416123 | F18: =F5/(1+D18/100)/$A$13 -> 1.1056348 | G18: =G5/(1+D18/100)/$A$13 -> 1.1696573 | H18: =H5/(1+D18/100)/$A$13 -> 1.2336799 | I18: =I5/(1+D18/100)/$A$13 -> 1.2977024 | J18: =J5/(1+D18/100)/$A$13 -> 1.3617249 | K18: =K5/(1+D18/100)/$A$13 -> 1.4257475 | L18: =L5/(1+D18/100)/$A$13 -> 1.48977 | N18: 2 | O18: =O5/(2+N18/100)/$A$13 -> 0.52596263 | P18: =P5/(2+N18/100)/$A$13 -> 0.55829084 | Q18: =Q5/(2+N18/100)/$A$13 -> 0.59061905 | R18: =R5/(2+N18/100)/$A$13 -> 0.62294726 | S18: =S5/(2+N18/100)/$A$13 -> 0.65527547 | T18: =T5/(2+N18/100)/$A$13 -> 0.68760368 | U18: =U5/(2+N18/100)/$A$13 -> 0.71993189 | V18: =V5/(2+N18/100)/$A$13 -> 0.7522601
A19: 6 | B19: 8.3838 | D19: 3 | E19: =E6/(1+D19/100)/$A$13 -> 1.0314995 | F19: =F6/(1+D19/100)/$A$13 -> 1.0949005 | G19: =G6/(1+D19/100)/$A$13 -> 1.1583014 | H19: =H6/(1+D19/100)/$A$13 -> 1.2217024 | I19: =I6/(1+D19/100)/$A$13 -> 1.2851033 | J19: =J6/(1+D19/100)/$A$13 -> 1.3485043 | K19: =K6/(1+D19/100)/$A$13 -> 1.4119053 | L19: =L6/(1+D19/100)/$A$13 -> 1.4753062 | N19: 3 | O19: =O6/(2+N19/100)/$A$13 -> 0.52337168 | P19: =P6/(2+N19/100)/$A$13 -> 0.55554064 | Q19: =Q6/(2+N19/100)/$A$13 -> 0.58770959 | R19: =R6/(2+N19/100)/$A$13 -> 0.61987855 | S19: =S6/(2+N19/100)/$A$13 -> 0.65204751 | T19: =T6/(2+N19/100)/$A$13 -> 0.68421647 | U19: =U6/(2+N19/100)/$A$13 -> 0.71638543 | V19: =V6/(2+N19/100)/$A$13 -> 0.74855439
A20: 5 | B20: 8.8633 | D20: 4 | E20: =E7/(1+D20/100)/$A$13 -> 1.0215813 | F20: =F7/(1+D20/100)/$A$13 -> 1.0843726 | G20: =G7/(1+D20/100)/$A$13 -> 1.1471639 | H20: =H7/(1+D20/100)/$A$13 -> 1.2099553 | I20: =I7/(1+D20/100)/$A$13 -> 1.2727466 | J20: =J7/(1+D20/100)/$A$13 -> 1.3355379 | K20: =K7/(1+D20/100)/$A$13 -> 1.3983292 | L20: =L7/(1+D20/100)/$A$13 -> 1.4611206 | N20: 4 | O20: =O7/(2+N20/100)/$A$13 -> 0.52080613 | P20: =P7/(2+N20/100)/$A$13 -> 0.5528174 | Q20: =Q7/(2+N20/100)/$A$13 -> 0.58482866 | R20: =R7/(2+N20/100)/$A$13 -> 0.61683993 | S20: =S7/(2+N20/100)/$A$13 -> 0.6488512 | T20: =T7/(2+N20/100)/$A$13 -> 0.68086247 | U20: =U7/(2+N20/100)/$A$13 -> 0.71287373 | V20: =V7/(2+N20/100)/$A$13 -> 0.744885
A21: 4 | B21: 9.3851 | D21: 5 | E21: =E8/(1+D21/100)/$A$13 -> 1.0118519 | F21: =F8/(1+D21/100)/$A$13 -> 1.0740452 | G21: =G8/(1+D21/100)/$A$13 -> 1.1362385 | H21: =H8/(1+D21/100)/$A$13 -> 1.1984319 | I21: =I8/(1+D21/100)/$A$13 -> 1.2606252 | J21: =J8/(1+D21/100)/$A$13 -> 1.3228185 | K21: =K8/(1+D21/100)/$A$13 -> 1.3850118 | L21: =L8/(1+D21/100)/$A$13 -> 1.4472051 | N21: 5 | O21: =O8/(2+N21/100)/$A$13 -> 0.51826561 | P21: =P8/(2+N21/100)/$A$13 -> 0.55012073 | Q21: =Q8/(2+N21/100)/$A$13 -> 0.58197584 | R21: =R8/(2+N21/100)/$A$13 -> 0.61383096 | S21: =S8/(2+N21/100)/$A$13 -> 0.64568607 | T21: =T8/(2+N21/100)/$A$13 -> 0.67754119 | U21: =U8/(2+N21/100)/$A$13 -> 0.7093963 | V21: =V8/(2+N21/100)/$A$13 -> 0.74125142
A22: 3 | B22: 9.954 | D22: 6 | E22: =E9/(1+D22/100)/$A$13 -> 1.0023061 | F22: =F9/(1+D22/100)/$A$13 -> 1.0639127 | G22: =G9/(1+D22/100)/$A$13 -> 1.1255193 | H22: =H9/(1+D22/100)/$A$13 -> 1.1871259 | I22: =I9/(1+D22/100)/$A$13 -> 1.2487325 | J22: =J9/(1+D22/100)/$A$13 -> 1.3103391 | K22: =K9/(1+D22/100)/$A$13 -> 1.3719457 | L22: =L9/(1+D22/100)/$A$13 -> 1.4335523 | N22: 6 | O22: =O9/(2+N22/100)/$A$13 -> 0.51574976 | P22: =P9/(2+N22/100)/$A$13 -> 0.54745024 | Q22: =Q9/(2+N22/100)/$A$13 -> 0.57915072 | R22: =R9/(2+N22/100)/$A$13 -> 0.61085119 | S22: =S9/(2+N22/100)/$A$13 -> 0.64255167 | T22: =T9/(2+N22/100)/$A$13 -> 0.67425215 | U22: =U9/(2+N22/100)/$A$13 -> 0.70595263 | V22: =V9/(2+N22/100)/$A$13 -> 0.73765311
A23: 2 | B23: 10.5753 | D23: 7 | E23: =E10/(1+D23/100)/$A$13 -> 0.99293879 | F23: =F10/(1+D23/100)/$A$13 -> 1.0539696 | G23: =G10/(1+D23/100)/$A$13 -> 1.1150004 | H23: =H10/(1+D23/100)/$A$13 -> 1.1760313 | I23: =I10/(1+D23/100)/$A$13 -> 1.2370621 | J23: =J10/(1+D23/100)/$A$13 -> 1.2980929 | K23: =K10/(1+D23/100)/$A$13 -> 1.3591238 | L23: =L10/(1+D23/100)/$A$13 -> 1.4201546 | N23: 7 | O23: =O10/(2+N23/100)/$A$13 -> 0.51325821 | P23: =P10/(2+N23/100)/$A$13 -> 0.54480555 | Q23: =Q10/(2+N23/100)/$A$13 -> 0.57635289 | R23: =R10/(2+N23/100)/$A$13 -> 0.60790022 | S23: =S10/(2+N23/100)/$A$13 -> 0.63944756 | T23: =T10/(2+N23/100)/$A$13 -> 0.67099489 | U23: =U10/(2+N23/100)/$A$13 -> 0.70254223 | V23: =V10/(2+N23/100)/$A$13 -> 0.73408957
A24: 1 | B24: 11.2551 | D24: 8 | E24: =E11/(1+D24/100)/$A$13 -> 0.98374491 | F24: =F11/(1+D24/100)/$A$13 -> 1.0442106 | G24: =G11/(1+D24/100)/$A$13 -> 1.1046764 | H24: =H11/(1+D24/100)/$A$13 -> 1.1651421 | I24: =I11/(1+D24/100)/$A$13 -> 1.2256078 | J24: =J11/(1+D24/100)/$A$13 -> 1.2860735 | K24: =K11/(1+D24/100)/$A$13 -> 1.3465393 | L24: =L11/(1+D24/100)/$A$13 -> 1.407005 | N24: 8 | O24: =O11/(2+N24/100)/$A$13 -> 0.51079063 | P24: =P11/(2+N24/100)/$A$13 -> 0.54218629 | Q24: =Q11/(2+N24/100)/$A$13 -> 0.57358196 | R24: =R11/(2+N24/100)/$A$13 -> 0.60497763 | S24: =S11/(2+N24/100)/$A$13 -> 0.63637329 | T24: =T11/(2+N24/100)/$A$13 -> 0.66776896 | U24: =U11/(2+N24/100)/$A$13 -> 0.69916462 | V24: =V11/(2+N24/100)/$A$13 -> 0.73056029
A25: 0 | B25: 12 | D25: 9 | E25: =E12/(1+D25/100)/$A$13 -> 0.97471973 | F25: =F12/(1+D25/100)/$A$13 -> 1.0346307 | G25: =G12/(1+D25/100)/$A$13 -> 1.0945417 | H25: =H12/(1+D25/100)/$A$13 -> 1.1544527 | I25: =I12/(1+D25/100)/$A$13 -> 1.2143637 | J25: =J12/(1+D25/100)/$A$13 -> 1.2742747 | K25: =K12/(1+D25/100)/$A$13 -> 1.3341857 | L25: =L12/(1+D25/100)/$A$13 -> 1.3940967 | N25: 9 | O25: =O12/(2+N25/100)/$A$13 -> 0.50834665 | P25: =P12/(2+N25/100)/$A$13 -> 0.5395921 | Q25: =Q12/(2+N25/100)/$A$13 -> 0.57083755 | R25: =R12/(2+N25/100)/$A$13 -> 0.602083 | S25: =S12/(2+N25/100)/$A$13 -> 0.63332844 | T25: =T12/(2+N25/100)/$A$13 -> 0.66457389 | U25: =U12/(2+N25/100)/$A$13 -> 0.69581934 | V25: =V12/(2+N25/100)/$A$13 -> 0.72706479
A26: Choosed Value | D26: 10 | E26: =E13/(1+D26/100)/$A$13 -> 0.96585864 | F26: =F13/(1+D26/100)/$A$13 -> 1.025225 | G26: =G13/(1+D26/100)/$A$13 -> 1.0845913 | H26: =H13/(1+D26/100)/$A$13 -> 1.1439577 | I26: =I13/(1+D26/100)/$A$13 -> 1.203324 | J26: =J13/(1+D26/100)/$A$13 -> 1.2626904 | K26: =K13/(1+D26/100)/$A$13 -> 1.3220567 | L26: =L13/(1+D26/100)/$A$13 -> 1.3814231 | N26: 10 | O26: =O13/(2+N26/100)/$A$13 -> 0.50592595 | P26: =P13/(2+N26/100)/$A$13 -> 0.53702261 | Q26: =Q13/(2+N26/100)/$A$13 -> 0.56811927 | R26: =R13/(2+N26/100)/$A$13 -> 0.59921593 | S26: =S13/(2+N26/100)/$A$13 -> 0.63031259 | T26: =T13/(2+N26/100)/$A$13 -> 0.66140925 | U26: =U13/(2+N26/100)/$A$13 -> 0.69250591 | V26: =V13/(2+N26/100)/$A$13 -> 0.72360257
A27: 11.2551
D29: Only consider electricity | N29: Include thermal power (treat as equal to pv power)
E30: O&M Ratio | O30: O&M Ratio
E31: 3 | F31: 4 | G31: 5 | H31: 6 | I31: 7 | J31: 8 | K31: 9 | L31: 10 | O31: 3 | P31: 4 | Q31: 5 | R31: 6 | S31: 7 | T31: 8 | U31: 9 | V31: 10
C32: Output Power Improvement Ratio | D32: 0 | E32: =E16 -> 1.1591239 | F32: =F16 -> 1.2566533 | G32: =G16 -> 1.3541828 | H32: =H16 -> 1.4517122 | I32: =I16 -> 1.5492416 | J32: =J16 -> 1.6467711 | K32: =K16 -> 1.7443005 | L32: =L16 -> 1.84183 | M32: Output Power Improvement Ratio | N32: 0 | O32: =O16 -> 0.57956194 | P32: =P16 -> 0.62832666 | Q32: =Q16 -> 0.67709138 | R32: =R16 -> 0.7258561 | S32: =S16 -> 0.77462082 | T32: =T16 -> 0.82338554 | U32: =U16 -> 0.87215027 | V32: =V16 -> 0.92091499
D33: 1 | E33: =E17 -> 1.0519253 | F33: =F17 -> 1.1165817 | G33: =G17 -> 1.1812381 | H33: =H17 -> 1.2458945 | I33: =I17 -> 1.3105509 | J33: =J17 -> 1.3752074 | K33: =K17 -> 1.4398638 | L33: =L17 -> 1.5045202 | N33: 1 | O33: =O17 -> 0.52857936 | P33: =P17 -> 0.5610684 | Q33: =Q17 -> 0.59355745 | R33: =R17 -> 0.6260465 | S33: =S17 -> 0.65853555 | T33: =T17 -> 0.69102459 | U33: =U17 -> 0.72351364 | V33: =V17 -> 0.75600269
D34: 2 | E34: =E18 -> 1.0416123 | F34: =F18 -> 1.1056348 | G34: =G18 -> 1.1696573 | H34: =H18 -> 1.2336799 | I34: =I18 -> 1.2977024 | J34: =J18 -> 1.3617249 | K34: =K18 -> 1.4257475 | L34: =L18 -> 1.48977 | N34: 2 | O34: =O18 -> 0.52596263 | P34: =P18 -> 0.55829084 | Q34: =Q18 -> 0.59061905 | R34: =R18 -> 0.62294726 | S34: =S18 -> 0.65527547 | T34: =T18 -> 0.68760368 | U34: =U18 -> 0.71993189 | V34: =V18 -> 0.7522601
D35: 3 | E35: =E19 -> 1.0314995 | F35: =F19 -> 1.0949005 | G35: =G19 -> 1.1583014 | H35: =H19 -> 1.2217024 | I35: =I19 -> 1.2851033 | J35: =J19 -> 1.3485043 | K35: =K19 -> 1.4119053 | L35: =L19 -> 1.4753062 | N35: 3 | O35: =O19 -> 0.52337168 | P35: =P19 -> 0.55554064 | Q35: =Q19 -> 0.58770959 | R35: =R19 -> 0.61987855 | S35: =S19 -> 0.65204751 | T35: =T19 -> 0.68421647 | U35: =U19 -> 0.71638543 | V35: =V19 -> 0.74855439
D36: 4 | E36: =E20 -> 1.0215813 | F36: =F20 -> 1.0843726 | G36: =G20 -> 1.1471639 | H36: =H20 -> 1.2099553 | I36: =I20 -> 1.2727466 | J36: =J20 -> 1.3355379 | K36: =K20 -> 1.3983292 | L36: =L20 -> 1.4611206 | N36: 4 | O36: =O20 -> 0.52080613 | P36: =P20 -> 0.5528174 | Q36: =Q20 -> 0.58482866 | R36: =R20 -> 0.61683993 | S36: =S20 -> 0.6488512 | T36: =T20 -> 0.68086247 | U36: =U20 -> 0.71287373 | V36: =V20 -> 0.744885
D37: 5 | E37: =E21 -> 1.0118519 | F37: =F21 -> 1.0740452 | G37: =G21 -> 1.1362385 | H37: =H21 -> 1.1984319 | I37: =I21 -> 1.2606252 | J37: =J21 -> 1.3228185 | K37: =K21 -> 1.3850118 | L37: =L21 -> 1.4472051 | N37: 5 | O37: =O21 -> 0.51826561 | P37: =P21 -> 0.55012073 | Q37: =Q21 -> 0.58197584 | R37: =R21 -> 0.61383096 | S37: =S21 -> 0.64568607 | T37: =T21 -> 0.67754119 | U37: =U21 -> 0.7093963 | V37: =V21 -> 0.74125142
D38: 6 | E38: =E22 -> 1.0023061 | F38: =F22 -> 1.0639127 | G38: =G22 -> 1.1255193 | H38: =H22 -> 1.1871259 | I38: =I22 -> 1.2487325 | J38: =J22 -> 1.3103391 | K38: =K22 -> 1.3719457 | L38: =L22 -> 1.4335523 | N38: 6 | O38: =O22 -> 0.51574976 | P38: =P22 -> 0.54745024 | Q38: =Q22 -> 0.57915072 | R38: =R22 -> 0.61085119 | S38: =S22 -> 0.64255167 | T38: =T22 -> 0.67425215 | U38: =U22 -> 0.70595263 | V38: =V22 -> 0.73765311
D39: 7 | E39: =E23 -> 0.99293879 | F39: =F23 -> 1.0539696 | G39: =G23 -> 1.1150004 | H39: =H23 -> 1.1760313 | I39: =I23 -> 1.2370621 | J39: =J23 -> 1.2980929 | K39: =K23 -> 1.3591238 | L39: =L23 -> 1.4201546 | N39: 7 | O39: =O23 -> 0.51325821 | P39: =P23 -> 0.54480555 | Q39: =Q23 -> 0.57635289 | R39: =R23 -> 0.60790022 | S39: =S23 -> 0.63944756 | T39: =T23 -> 0.67099489 | U39: =U23 -> 0.70254223 | V39: =V23 -> 0.73408957
D40: 8 | E40: =E24 -> 0.98374491 | F40: =F24 -> 1.0442106 | G40: =G24 -> 1.1046764 | H40: =H24 -> 1.1651421 | I40: =I24 -> 1.2256078 | J40: =J24 -> 1.2860735 | K40: =K24 -> 1.3465393 | L40: =L24 -> 1.407005 | N40: 8 | O40: =O24 -> 0.51079063 | P40: =P24 -> 0.54218629 | Q40: =Q24 -> 0.57358196 | R40: =R24 -> 0.60497763 | S40: =S24 -> 0.63637329 | T40: =T24 -> 0.66776896 | U40: =U24 -> 0.69916462 | V40: =V24 -> 0.73056029
D41: 9 | E41: =E25 -> 0.97471973 | F41: =F25 -> 1.0346307 | G41: =G25 -> 1.0945417 | H41: =H25 -> 1.1544527 | I41: =I25 -> 1.2143637 | J41: =J25 -> 1.2742747 | K41: =K25 -> 1.3341857 | L41: =L25 -> 1.3940967 | N41: 9 | O41: =O25 -> 0.50834665 | P41: =P25 -> 0.5395921 | Q41: =Q25 -> 0.57083755 | R41: =R25 -> 0.602083 | S41: =S25 -> 0.63332844 | T41: =T25 -> 0.66457389 | U41: =U25 -> 0.69581934 | V41: =V25 -> 0.72706479
D42: 10 | E42: =E26 -> 0.96585864 | F42: =F26 -> 1.025225 | G42: =G26 -> 1.0845913 | H42: =H26 -> 1.1439577 | I42: =I26 -> 1.203324 | J42: =J26 -> 1.2626904 | K42: =K26 -> 1.3220567 | L42: =L26 -> 1.3814231 | N42: 10 | O42: =O26 -> 0.50592595 | P42: =P26 -> 0.53702261 | Q42: =Q26 -> 0.56811927 | R42: =R26 -> 0.59921593 | S42: =S26 -> 0.63031259 | T42: =T26 -> 0.66140925 | U42: =U26 -> 0.69250591 | V42: =V26 -> 0.72360257

Sheet Flat plate PVT result
A1: PV Total Lifetime Cost | D1: Flat plate PV/T
A2: Discount Ratio | B2: Value | E2: 3 | F2: 4 | G2: 5 | H2: 6 | I2: 7 | J2: 8 | K2: 9 | L2: 10 | O2: 3 | P2: 4 | Q2: 5 | R2: 6 | S2: 7 | T2: 8 | U2: 9 | V2: 10
A3: 8 | B3: =Data!$B$24+Data!$B$24*0.03*Data!B13 -> 84.526162 | D3: 0 | E3: =(Data!$H$24)+(Data!$H$24)*E2/100*$A$27 -> 99.962809 | F3: =(Data!$H$24)+(Data!$H$24)*F2/100*$A$27 -> 108.37374 | G3: =(Data!$H$24)+(Data!$H$24)*G2/100*$A$27 -> 116.78468 | H3: =(Data!$H$24)+(Data!$H$24)*H2/100*$A$27 -> 125.19562 | I3: =(Data!$H$24)+(Data!$H$24)*I2/100*$A$27 -> 133.60655 | J3: =(Data!$H$24)+(Data!$H$24)*J2/100*$A$27 -> 142.01749 | K3: =(Data!$H$24)+(Data!$H$24)*K2/100*$A$27 -> 150.42843 | L3: =(Data!$H$24)+(Data!$H$24)*L2/100*$A$27 -> 158.83936 | N3: 0 | O3: =(Data!$H$24)+(Data!$H$24)*O2/100*$A$27 -> 99.962809 | P3: =(Data!$H$24)+(Data!$H$24)*P2/100*$A$27 -> 108.37374 | Q3: =(Data!$H$24)+(Data!$H$24)*Q2/100*$A$27 -> 116.78468 | R3: =(Data!$H$24)+(Data!$H$24)*R2/100*$A$27 -> 125.19562 | S3: =(Data!$H$24)+(Data!$H$24)*S2/100*$A$27 -> 133.60655 | T3: =(Data!$H$24)+(Data!$H$24)*T2/100*$A$27 -> 142.01749 | U3: =(Data!$H$24)+(Data!$H$24)*U2/100*$A$27 -> 150.42843 | V3: =(Data!$H$24)+(Data!$H$24)*V2/100*$A$27 -> 158.83936
A4: 7 | B4: =Data!$B$24+Data!$B$24*0.03*Data!B14 -> 85.367092 | D4: 1 | E4: 91.625183 | F4: 97.25691 | G4: 102.88864 | H4: 108.52037 | I4: 114.15209 | J4: 119.78382 | K4: 125.41555 | L4: 131.04728 | N4: 1 | O4: 91.625183 | P4: 97.25691 | Q4: 102.88864 | R4: 108.52037 | S4: 114.15209 | T4: 119.78382 | U4: 125.41555 | V4: 131.04728
A5: 6 | B5: =Data!$B$24+Data!$B$24*0.03*Data!B15 -> 86.279375 | D5: 2 | E5: 91.625183 | F5: 97.25691 | G5: 102.88864 | H5: 108.52037 | I5: 114.15209 | J5: 119.78382 | K5: 125.41555 | L5: 131.04728 | N5: 2 | O5: 91.625183 | P5: 97.25691 | Q5: 102.88864 | R5: 108.52037 | S5: 114.15209 | T5: 119.78382 | U5: 125.41555 | V5: 131.04728
A6: 5 | B6: =Data!$B$24+Data!$B$24*0.03*Data!B16 -> 87.271077 | D6: 3 | E6: 91.625183 | F6: 97.25691 | G6: 102.88864 | H6: 108.52037 | I6: 114.15209 | J6: 119.78382 | K6: 125.41555 | L6: 131.04728 | N6: 3 | O6: 91.625183 | P6: 97.25691 | Q6: 102.88864 | R6: 108.52037 | S6: 114.15209 | T6: 119.78382 | U6: 125.41555 | V6: 131.04728
A7: 4 | B7: =Data!$B$24+Data!$B$24*0.03*Data!B17 -> 88.350264 | D7: 4 | E7: 91.625183 | F7: 97.25691 | G7: 102.88864 | H7: 108.52037 | I7: 114.15209 | J7: 119.78382 | K7: 125.41555 | L7: 131.04728 | N7: 4 | O7: 91.625183 | P7: 97.25691 | Q7: 102.88864 | R7: 108.52037 | S7: 114.15209 | T7: 119.78382 | U7: 125.41555 | V7: 131.04728
A8: 3 | B8: =Data!$B$24+Data!$B$24*0.03*Data!B18 -> 89.526863 | D8: 5 | E8: 91.625183 | F8: 97.25691 | G8: 102.88864 | H8: 108.52037 | I8: 114.15209 | J8: 119.78382 | K8: 125.41555 | L8: 131.04728 | N8: 5 | O8: 91.625183 | P8: 97.25691 | Q8: 102.88864 | R8: 108.52037 | S8: 114.15209 | T8: 119.78382 | U8: 125.41555 | V8: 131.04728
A9: 2 | B9: =Data!$B$24+Data!$B$24*0.03*Data!B19 -> 90.811835 | D9: 6 | E9: 91.625183 | F9: 97.25691 | G9: 102.88864 | H9: 108.52037 | I9: 114.15209 | J9: 119.78382 | K9: 125.41555 | L9: 131.04728 | N9: 6 | O9: 91.625183 | P9: 97.25691 | Q9: 102.88864 | R9: 108.52037 | S9: 114.15209 | T9: 119.78382 | U9: 125.41555 | V9: 131.04728
A10: 1 | B10: =Data!$B$24+Data!$B$24*0.03*Data!B20 -> 92.217798 | D10: 7 | E10: 91.625183 | F10: 97.25691 | G10: 102.88864 | H10: 108.52037 | I10: 114.15209 | J10: 119.78382 | K10: 125.41555 | L10: 131.04728 | N10: 7 | O10: 91.625183 | P10: 97.25691 | Q10: 102.88864 | R10: 108.52037 | S10: 114.15209 | T10: 119.78382 | U10: 125.41555 | V10: 131.04728
A11: 0 | B11: =Data!$B$24+Data!$B$24*0.03*Data!B21 -> 93.7584 | D11: 8 | E11: 91.625183 | F11: 97.25691 | G11: 102.88864 | H11: 108.52037 | I11: 114.15209 | J11: 119.78382 | K11: 125.41555 | L11: 131.04728 | N11: 8 | O11: 91.625183 | P11: 97.25691 | Q11: 102.88864 | R11: 108.52037 | S11: 114.15209 | T11: 119.78382 | U11: 125.41555 | V11: 131.04728
A12: Choosed Value | D12: 9 | E12: 91.625183 | F12: 97.25691 | G12: 102.88864 | H12: 108.52037 | I12: 114.15209 | J12: 119.78382 | K12: 125.41555 | L12: 131.04728 | N12: 9 | O12: 91.625183 | P12: 97.25691 | Q12: 102.88864 | R12: 108.52037 | S12: 114.15209 | T12: 119.78382 | U12: 125.41555 | V12: 131.04728
A13: 92.217798 | D13: 10 | E13: 91.625183 | F13: 97.25691 | G13: 102.88864 | H13: 108.52037 | I13: 114.15209 | J13: 119.78382 | K13: 125.41555 | L13: 131.04728 | N13: 10 | O13: 91.625183 | P13: 97.25691 | Q13: 102.88864 | R13: 108.52037 | S13: 114.15209 | T13: 119.78382 | U13: 125.41555 | V13: 131.04728
A15: PVIFA | E15: 3 | F15: 4 | G15: 5 | H15: 6 | I15: 7 | J15: 8 | K15: 9 | L15: 10 | O15: 3 | P15: 4 | Q15: 5 | R15: 6 | S15: 7 | T15: 8 | U15: 9 | V15: 10
A16: Discount Ratio | B16: Value | D16: 0 | E16: =E3/(1+$D$16/100)/$A$13 -> 1.0839861 | F16: =F3/(1+$D$16/100)/$A$13 -> 1.1751934 | G16: =G3/(1+$D$16/100)/$A$13 -> 1.2664007 | H16: =H3/(1+$D$16/100)/$A$13 -> 1.357608 | I16: =I3/(1+$D$16/100)/$A$13 -> 1.4488153 | J16: =J3/(1+$D$16/100)/$A$13 -> 1.5400226 | K16: =K3/(1+$D$16/100)/$A$13 -> 1.6312299 | L16: =L3/(1+$D$16/100)/$A$13 -> 1.7224372 | N16: 0 | O16: =O3/(2+$D$16/100)/$A$13 -> 0.54199304 | P16: =P3/(2+$D$16/100)/$A$13 -> 0.58759669 | Q16: =Q3/(2+$D$16/100)/$A$13 -> 0.63320034 | R16: =R3/(2+$D$16/100)/$A$13 -> 0.67880399 | S16: =S3/(2+$D$16/100)/$A$13 -> 0.72440763 | T16: =T3/(2+$D$16/100)/$A$13 -> 0.77001128 | U16: =U3/(2+$D$16/100)/$A$13 -> 0.81561493 | V16: =V3/(2+$D$16/100)/$A$13 -> 0.86121858
A17: 8 | B17: 7.5361 | D17: 1 | E17: =E4/(1+D17/100)/$A$13 -> 0.98373638 | F17: =F4/(1+D17/100)/$A$13 -> 1.0442016 | G17: =G4/(1+D17/100)/$A$13 -> 1.1046668 | H17: =H4/(1+D17/100)/$A$13 -> 1.165132 | I17: =I4/(1+D17/100)/$A$13 -> 1.2255972 | J17: =J4/(1+D17/100)/$A$13 -> 1.2860624 | K17: =K4/(1+D17/100)/$A$13 -> 1.3465276 | L17: =L4/(1+D17/100)/$A$13 -> 1.4069928 | N17: 1 | O17: =O4/(2+N17/100)/$A$13 -> 0.4943153 | P17: =P4/(2+N17/100)/$A$13 -> 0.52469831 | Q17: =Q4/(2+N17/100)/$A$13 -> 0.55508132 | R17: =R4/(2+N17/100)/$A$13 -> 0.58546433 | S17: =S4/(2+N17/100)/$A$13 -> 0.61584734 | T17: =T4/(2+N17/100)/$A$13 -> 0.64623036 | U17: =U4/(2+N17/100)/$A$13 -> 0.67661337 | V17: =V4/(2+N17/100)/$A$13 -> 0.70699638
A18: 7 | B18: 7.9427 | D18: 2 | E18: =E5/(1+D18/100)/$A$13 -> 0.97409191 | F18: =F5/(1+D18/100)/$A$13 -> 1.0339643 | G18: =G5/(1+D18/100)/$A$13 -> 1.0938367 | H18: =H5/(1+D18/100)/$A$13 -> 1.1537091 | I18: =I5/(1+D18/100)/$A$13 -> 1.2135815 | J18: =J5/(1+D18/100)/$A$13 -> 1.2734539 | K18: =K5/(1+D18/100)/$A$13 -> 1.3333263 | L18: =L5/(1+D18/100)/$A$13 -> 1.3931988 | N18: 2 | O18: =O5/(2+N18/100)/$A$13 -> 0.49186819 | P18: =P5/(2+N18/100)/$A$13 -> 0.52210079 | Q18: =Q5/(2+N18/100)/$A$13 -> 0.55233339 | R18: =R5/(2+N18/100)/$A$13 -> 0.58256599 | S18: =S5/(2+N18/100)/$A$13 -> 0.6127986 | T18: =T5/(2+N18/100)/$A$13 -> 0.6430312 | U18: =U5/(2+N18/100)/$A$13 -> 0.6732638 | V18: =V5/(2+N18/100)/$A$13 -> 0.7034964
A19: 6 | B19: 8.3838 | D19: 3 | E19: =E6/(1+D19/100)/$A$13 -> 0.9646347 | F19: =F6/(1+D19/100)/$A$13 -> 1.0239258 | G19: =G6/(1+D19/100)/$A$13 -> 1.0832169 | H19: =H6/(1+D19/100)/$A$13 -> 1.1425081 | I19: =I6/(1+D19/100)/$A$13 -> 1.2017992 | J19: =J6/(1+D19/100)/$A$13 -> 1.2610903 | K19: =K6/(1+D19/100)/$A$13 -> 1.3203814 | L19: =L6/(1+D19/100)/$A$13 -> 1.3796726 | N19: 3 | O19: =O6/(2+N19/100)/$A$13 -> 0.48944519 | P19: =P6/(2+N19/100)/$A$13 -> 0.51952887 | Q19: =Q6/(2+N19/100)/$A$13 -> 0.54961254 | R19: =R6/(2+N19/100)/$A$13 -> 0.57969621 | S19: =S6/(2+N19/100)/$A$13 -> 0.60977988 | T19: =T6/(2+N19/100)/$A$13 -> 0.63986356 | U19: =U6/(2+N19/100)/$A$13 -> 0.66994723 | V19: =V6/(2+N19/100)/$A$13 -> 0.7000309
A20: 5 | B20: 8.8633 | D20: 4 | E20: =E7/(1+D20/100)/$A$13 -> 0.95535937 | F20: =F7/(1+D20/100)/$A$13 -> 1.0140804 | G20: =G7/(1+D20/100)/$A$13 -> 1.0728014 | H20: =H7/(1+D20/100)/$A$13 -> 1.1315224 | I20: =I7/(1+D20/100)/$A$13 -> 1.1902434 | J20: =J7/(1+D20/100)/$A$13 -> 1.2489644 | K20: =K7/(1+D20/100)/$A$13 -> 1.3076855 | L20: =L7/(1+D20/100)/$A$13 -> 1.3664065 | N20: 4 | O20: =O7/(2+N20/100)/$A$13 -> 0.48704595 | P20: =P7/(2+N20/100)/$A$13 -> 0.51698216 | Q20: =Q7/(2+N20/100)/$A$13 -> 0.54691836 | R20: =R7/(2+N20/100)/$A$13 -> 0.57685456 | S20: =S7/(2+N20/100)/$A$13 -> 0.60679077 | T20: =T7/(2+N20/100)/$A$13 -> 0.63672697 | U20: =U7/(2+N20/100)/$A$13 -> 0.66666317 | V20: =V7/(2+N20/100)/$A$13 -> 0.69659938
A21: 4 | B21: 9.3851 | D21: 5 | E21: =E8/(1+D21/100)/$A$13 -> 0.94626071 | F21: =F8/(1+D21/100)/$A$13 -> 1.0044225 | G21: =G8/(1+D21/100)/$A$13 -> 1.0625842 | H21: =H8/(1+D21/100)/$A$13 -> 1.120746 | I21: =I8/(1+D21/100)/$A$13 -> 1.1789078 | J21: =J8/(1+D21/100)/$A$13 -> 1.2370695 | K21: =K8/(1+D21/100)/$A$13 -> 1.2952313 | L21: =L8/(1+D21/100)/$A$13 -> 1.3533931 | N21: 5 | O21: =O8/(2+N21/100)/$A$13 -> 0.48467012 | P21: =P8/(2+N21/100)/$A$13 -> 0.51446029 | Q21: =Q8/(2+N21/100)/$A$13 -> 0.54425046 | R21: =R8/(2+N21/100)/$A$13 -> 0.57404064 | S21: =S8/(2+N21/100)/$A$13 -> 0.60383081 | T21: =T8/(2+N21/100)/$A$13 -> 0.63362098 | U21: =U8/(2+N21/100)/$A$13 -> 0.66341116 | V21: =V8/(2+N21/100)/$A$13 -> 0.69320133
A22: 3 | B22: 9.954 | D22: 6 | E22: =E9/(1+D22/100)/$A$13 -> 0.93733372 | F22: =F9/(1+D22/100)/$A$13 -> 0.99494679 | G22: =G9/(1+D22/100)/$A$13 -> 1.0525599 | H22: =H9/(1+D22/100)/$A$13 -> 1.1101729 | I22: =I9/(1+D22/100)/$A$13 -> 1.167786 | J22: =J9/(1+D22/100)/$A$13 -> 1.2253991 | K22: =K9/(1+D22/100)/$A$13 -> 1.2830121 | L22: =L9/(1+D22/100)/$A$13 -> 1.3406252 | N22: 6 | O22: =O9/(2+N22/100)/$A$13 -> 0.48231735 | P22: =P9/(2+N22/100)/$A$13 -> 0.51196291 | Q22: =Q9/(2+N22/100)/$A$13 -> 0.54160847 | R22: =R9/(2+N22/100)/$A$13 -> 0.57125403 | S22: =S9/(2+N22/100)/$A$13 -> 0.60089959 | T22: =T9/(2+N22/100)/$A$13 -> 0.63054515 | U22: =U9/(2+N22/100)/$A$13 -> 0.66019071 | V22: =V9/(2+N22/100)/$A$13 -> 0.68983628
A23: 2 | B23: 10.5753 | D23: 7 | E23: =E10/(1+D23/100)/$A$13 -> 0.92857359 | F23: =F10/(1+D23/100)/$A$13 -> 0.98564822 | G23: =G10/(1+D23/100)/$A$13 -> 1.0427229 | H23: =H10/(1+D23/100)/$A$13 -> 1.0997975 | I23: =I10/(1+D23/100)/$A$13 -> 1.1568721 | J23: =J10/(1+D23/100)/$A$13 -> 1.2139467 | K23: =K10/(1+D23/100)/$A$13 -> 1.2710214 | L23: =L10/(1+D23/100)/$A$13 -> 1.328096 | N23: 7 | O23: =O10/(2+N23/100)/$A$13 -> 0.47998732 | P23: =P10/(2+N23/100)/$A$13 -> 0.50948966 | Q23: =Q10/(2+N23/100)/$A$13 -> 0.53899201 | R23: =R10/(2+N23/100)/$A$13 -> 0.56849435 | S23: =S10/(2+N23/100)/$A$13 -> 0.5979967 | T23: =T10/(2+N23/100)/$A$13 -> 0.62749904 | U23: =U10/(2+N23/100)/$A$13 -> 0.65700139 | V23: =V10/(2+N23/100)/$A$13 -> 0.68650373
A24: 1 | B24: 11.2551 | D24: 8 | E24: =E11/(1+D24/100)/$A$13 -> 0.91997569 | F24: =F11/(1+D24/100)/$A$13 -> 0.97652185 | G24: =G11/(1+D24/100)/$A$13 -> 1.033068 | H24: =H11/(1+D24/100)/$A$13 -> 1.0896142 | I24: =I11/(1+D24/100)/$A$13 -> 1.1461603 | J24: =J11/(1+D24/100)/$A$13 -> 1.2027065 | K24: =K11/(1+D24/100)/$A$13 -> 1.2592527 | L24: =L11/(1+D24/100)/$A$13 -> 1.3157988 | N24: 8 | O24: =O11/(2+N24/100)/$A$13 -> 0.47767968 | P24: =P11/(2+N24/100)/$A$13 -> 0.50704019 | Q24: =Q11/(2+N24/100)/$A$13 -> 0.5364007 | R24: =R11/(2+N24/100)/$A$13 -> 0.56576121 | S24: =S11/(2+N24/100)/$A$13 -> 0.59512171 | T24: =T11/(2+N24/100)/$A$13 -> 0.62448222 | U24: =U11/(2+N24/100)/$A$13 -> 0.65384273 | V24: =V11/(2+N24/100)/$A$13 -> 0.68320323
A25: 0 | B25: 12 | D25: 9 | E25: =E12/(1+D25/100)/$A$13 -> 0.91153554 | F25: =F12/(1+D25/100)/$A$13 -> 0.96756293 | G25: =G12/(1+D25/100)/$A$13 -> 1.0235903 | H25: =H12/(1+D25/100)/$A$13 -> 1.0796177 | I25: =I12/(1+D25/100)/$A$13 -> 1.1356451 | J25: =J12/(1+D25/100)/$A$13 -> 1.1916725 | K25: =K12/(1+D25/100)/$A$13 -> 1.2476999 | L25: =L12/(1+D25/100)/$A$13 -> 1.3037273 | N25: 9 | O25: =O12/(2+N25/100)/$A$13 -> 0.47539414 | P25: =P12/(2+N25/100)/$A$13 -> 0.50461416 | Q25: =Q12/(2+N25/100)/$A$13 -> 0.53383419 | R25: =R12/(2+N25/100)/$A$13 -> 0.56305421 | S25: =S12/(2+N25/100)/$A$13 -> 0.59227424 | T25: =T12/(2+N25/100)/$A$13 -> 0.62149427 | U25: =U12/(2+N25/100)/$A$13 -> 0.65071429 | V25: =V12/(2+N25/100)/$A$13 -> 0.67993432
A26: Choosed Value | D26: 10 | E26: =E13/(1+D26/100)/$A$13 -> 0.90324886 | F26: =F13/(1+D26/100)/$A$13 -> 0.95876691 | G26: =G13/(1+D26/100)/$A$13 -> 1.014285 | H26: =H13/(1+D26/100)/$A$13 -> 1.069803 | I26: =I13/(1+D26/100)/$A$13 -> 1.1253211 | J26: =J13/(1+D26/100)/$A$13 -> 1.1808391 | K26: =K13/(1+D26/100)/$A$13 -> 1.2363572 | L26: =L13/(1+D26/100)/$A$13 -> 1.2918752 | N26: 10 | O26: =O13/(2+N26/100)/$A$13 -> 0.47313035 | P26: =P13/(2+N26/100)/$A$13 -> 0.50221124 | Q26: =Q13/(2+N26/100)/$A$13 -> 0.53129212 | R26: =R13/(2+N26/100)/$A$13 -> 0.560373 | S26: =S13/(2+N26/100)/$A$13 -> 0.58945389 | T26: =T13/(2+N26/100)/$A$13 -> 0.61853477 | U26: =U13/(2+N26/100)/$A$13 -> 0.64761565 | V26: =V13/(2+N26/100)/$A$13 -> 0.67669654
A27: 11.2551
D29: Only consider electricity | N29: Include thermal power (treat as equal to pv power)
E30: O&M Ratio | O30: O&M Ratio
E31: 3 | F31: 4 | G31: 5 | H31: 6 | I31: 7 | J31: 8 | K31: 9 | L31: 10 | O31: 3 | P31: 4 | Q31: 5 | R31: 6 | S31: 7 | T31: 8 | U31: 9 | V31: 10
C32: Output Power Improvement Ratio | D32: 0 | E32: =E16 -> 1.0839861 | F32: =F16 -> 1.1751934 | G32: =G16 -> 1.2664007 | H32: =H16 -> 1.357608 | I32: =I16 -> 1.4488153 | J32: =J16 -> 1.5400226 | K32: =K16 -> 1.6312299 | L32: =L16 -> 1.7224372 | M32: Output Power Improvement Ratio | N32: 0 | O32: =O16 -> 0.54199304 | P32: =P16 -> 0.58759669 | Q32: =Q16 -> 0.63320034 | R32: =R16 -> 0.67880399 | S32: =S16 -> 0.72440763 | T32: =T16 -> 0.77001128 | U32: =U16 -> 0.81561493 | V32: =V16 -> 0.86121858
D33: 1 | E33: =E17 -> 0.98373638 | F33: =F17 -> 1.0442016 | G33: =G17 -> 1.1046668 | H33: =H17 -> 1.165132 | I33: =I17 -> 1.2255972 | J33: =J17 -> 1.2860624 | K33: =K17 -> 1.3465276 | L33: =L17 -> 1.4069928 | N33: 1 | O33: =O17 -> 0.4943153 | P33: =P17 -> 0.52469831 | Q33: =Q17 -> 0.55508132 | R33: =R17 -> 0.58546433 | S33: =S17 -> 0.61584734 | T33: =T17 -> 0.64623036 | U33: =U17 -> 0.67661337 | V33: =V17 -> 0.70699638
D34: 2 | E34: =E18 -> 0.97409191 | F34: =F18 -> 1.0339643 | G34: =G18 -> 1.0938367 | H34: =H18 -> 1.1537091 | I34: =I18 -> 1.2135815 | J34: =J18 -> 1.2734539 | K34: =K18 -> 1.3333263 | L34: =L18 -> 1.3931988 | N34: 2 | O34: =O18 -> 0.49186819 | P34: =P18 -> 0.52210079 | Q34: =Q18 -> 0.55233339 | R34: =R18 -> 0.58256599 | S34: =S18 -> 0.6127986 | T34: =T18 -> 0.6430312 | U34: =U18 -> 0.6732638 | V34: =V18 -> 0.7034964
D35: 3 | E35: =E19 -> 0.9646347 | F35: =F19 -> 1.0239258 | G35: =G19 -> 1.0832169 | H35: =H19 -> 1.1425081 | I35: =I19 -> 1.2017992 | J35: =J19 -> 1.2610903 | K35: =K19 -> 1.3203814 | L35: =L19 -> 1.3796726 | N35: 3 | O35: =O19 -> 0.48944519 | P35: =P19 -> 0.51952887 | Q35: =Q19 -> 0.54961254 | R35: =R19 -> 0.57969621 | S35: =S19 -> 0.60977988 | T35: =T19 -> 0.63986356 | U35: =U19 -> 0.66994723 | V35: =V19 -> 0.7000309
D36: 4 | E36: =E20 -> 0.95535937 | F36: =F20 -> 1.0140804 | G36: =G20 -> 1.0728014 | H36: =H20 -> 1.1315224 | I36: =I20 -> 1.1902434 | J36: =J20 -> 1.2489644 | K36: =K20 -> 1.3076855 | L36: =L20 -> 1.3664065 | N36: 4 | O36: =O20 -> 0.48704595 | P36: =P20 -> 0.51698216 | Q36: =Q20 -> 0.54691836 | R36: =R20 -> 0.57685456 | S36: =S20 -> 0.60679077 | T36: =T20 -> 0.63672697 | U36: =U20 -> 0.66666317 | V36: =V20 -> 0.69659938
D37: 5 | E37: =E21 -> 0.94626071 | F37: =F21 -> 1.0044225 | G37: =G21 -> 1.0625842 | H37: =H21 -> 1.120746 | I37: =I21 -> 1.1789078 | J37: =J21 -> 1.2370695 | K37: =K21 -> 1.2952313 | L37: =L21 -> 1.3533931 | N37: 5 | O37: =O21 -> 0.48467012 | P37: =P21 -> 0.51446029 | Q37: =Q21 -> 0.54425046 | R37: =R21 -> 0.57404064 | S37: =S21 -> 0.60383081 | T37: =T21 -> 0.63362098 | U37: =U21 -> 0.66341116 | V37: =V21 -> 0.69320133
D38: 6 | E38: =E22 -> 0.93733372 | F38: =F22 -> 0.99494679 | G38: =G22 -> 1.0525599 | H38: =H22 -> 1.1101729 | I38: =I22 -> 1.167786 | J38: =J22 -> 1.2253991 | K38: =K22 -> 1.2830121 | L38: =L22 -> 1.3406252 | N38: 6 | O38: =O22 -> 0.48231735 | P38: =P22 -> 0.51196291 | Q38: =Q22 -> 0.54160847 | R38: =R22 -> 0.57125403 | S38: =S22 -> 0.60089959 | T38: =T22 -> 0.63054515 | U38: =U22 -> 0.66019071 | V38: =V22 -> 0.68983628
D39: 7 | E39: =E23 -> 0.92857359 | F39: =F23 -> 0.98564822 | G39: =G23 -> 1.0427229 | H39: =H23 -> 1.0997975 | I39: =I23 -> 1.1568721 | J39: =J23 -> 1.2139467 | K39: =K23 -> 1.2710214 | L39: =L23 -> 1.328096 | N39: 7 | O39: =O23 -> 0.47998732 | P39: =P23 -> 0.50948966 | Q39: =Q23 -> 0.53899201 | R39: =R23 -> 0.56849435 | S39: =S23 -> 0.5979967 | T39: =T23 -> 0.62749904 | U39: =U23 -> 0.65700139 | V39: =V23 -> 0.68650373
D40: 8 | E40: =E24 -> 0.91997569 | F40: =F24 -> 0.97652185 | G40: =G24 -> 1.033068 | H40: =H24 -> 1.0896142 | I40: =I24 -> 1.1461603 | J40: =J24 -> 1.2027065 | K40: =K24 -> 1.2592527 | L40: =L24 -> 1.3157988 | N40: 8 | O40: =O24 -> 0.47767968 | P40: =P24 -> 0.50704019 | Q40: =Q24 -> 0.5364007 | R40: =R24 -> 0.56576121 | S40: =S24 -> 0.59512171 | T40: =T24 -> 0.62448222 | U40: =U24 -> 0.65384273 | V40: =V24 -> 0.68320323
D41: 9 | E41: =E25 -> 0.91153554 | F41: =F25 -> 0.96756293 | G41: =G25 -> 1.0235903 | H41: =H25 -> 1.0796177 | I41: =I25 -> 1.1356451 | J41: =J25 -> 1.1916725 | K41: =K25 -> 1.2476999 | L41: =L25 -> 1.3037273 | N41: 9 | O41: =O25 -> 0.47539414 | P41: =P25 -> 0.50461416 | Q41: =Q25 -> 0.53383419 | R41: =R25 -> 0.56305421 | S41: =S25 -> 0.59227424 | T41: =T25 -> 0.62149427 | U41: =U25 -> 0.65071429 | V41: =V25 -> 0.67993432
D42: 10 | E42: =E26 -> 0.90324886 | F42: =F26 -> 0.95876691 | G42: =G26 -> 1.014285 | H42: =H26 -> 1.069803 | I42: =I26 -> 1.1253211 | J42: =J26 -> 1.1808391 | K42: =K26 -> 1.2363572 | L42: =L26 -> 1.2918752 | N42: 10 | O42: =O26 -> 0.47313035 | P42: =P26 -> 0.50221124 | Q42: =Q26 -> 0.53129212 | R42: =R26 -> 0.560373 | S42: =S26 -> 0.58945389 | T42: =T26 -> 0.61853477 | U42: =U26 -> 0.64761565 | V42: =V26 -> 0.67669654
